Experiment 'pythonTerminalEnvVarActivation' is active
LSP Notebooks experiment is disabled -- not using Pylance
LSP Notebooks interactive window support is disabled -- not in LSP Notebooks experiment
> poetry env list --full-path
cwd: .
[ERROR 2025-5-9 16:31:21.845]: [Error: Command failed: poetry env list --full-path
/bin/sh: 1: poetry: not found

	at ChildProcess.exithandler (node:child_process:419:12)
	at ChildProcess.emit (node:events:513:28)
	at maybeClose (node:internal/child_process:1091:16)
	at Socket.<anonymous> (node:internal/child_process:449:11)
	at Socket.emit (node:events:513:28)
	at Pipe.<anonymous> (node:net:322:12)] {
  code: 127,
  killed: false,
  signal: null,
  cmd: 'poetry env list --full-path'
}
> conda info --json
> ./.conda/bin/python -I ~/.local/share/code-server/extensions/ms-python.python-2023.4.1/pythonFiles/get_output_via_markers.py ~/.local/share/code-server/extensions/ms-python.python-2023.4.1/pythonFiles/interpreterInfo.py
Python interpreter path: ./.conda/bin/python
Starting Jedi language server for code.
> conda run -p ./.conda --no-capture-output python ~/.local/share/code-server/extensions/ms-python.python-2023.4.1/pythonFiles/get_output_via_markers.py ~/.local/share/code-server/extensions/ms-python.python-2023.4.1/pythonFiles/printEnvVariables.py
> /opt/conda/bin/python -I ~/.local/share/code-server/extensions/ms-python.python-2023.4.1/pythonFiles/get_output_via_markers.py ~/.local/share/code-server/extensions/ms-python.python-2023.4.1/pythonFiles/interpreterInfo.py
> /bin/python3 -I ~/.local/share/code-server/extensions/ms-python.python-2023.4.1/pythonFiles/get_output_via_markers.py ~/.local/share/code-server/extensions/ms-python.python-2023.4.1/pythonFiles/interpreterInfo.py
> /usr/bin/python3 -I ~/.local/share/code-server/extensions/ms-python.python-2023.4.1/pythonFiles/get_output_via_markers.py ~/.local/share/code-server/extensions/ms-python.python-2023.4.1/pythonFiles/interpreterInfo.py
> conda run -p ./.conda --no-capture-output python ~/.local/share/code-server/extensions/ms-python.python-2023.4.1/pythonFiles/get_output_via_markers.py ~/.local/share/code-server/extensions/ms-python.python-2023.4.1/pythonFiles/printEnvVariables.py
> conda run -p ./.conda --no-capture-output python ~/.local/share/code-server/extensions/ms-python.python-2023.4.1/pythonFiles/get_output_via_markers.py ~/.local/share/code-server/extensions/ms-python.python-2023.4.1/pythonFiles/printEnvVariables.py
> conda info --json
Running Conda Env creation script:  [
  '/opt/conda/bin/python',
  '/home/ubuntu/.local/share/code-server/extensions/ms-python.python-2023.4.1/pythonFiles/create_conda.py',
  '--git-ignore',
  '--install',
  '--python',
  '3.11'
]
EXISTING_CONDA_ENV:/mnt/code/.conda
> conda run -p ./.conda --no-capture-output python ~/.local/share/code-server/extensions/ms-python.python-2023.4.1/pythonFiles/get_output_via_markers.py ~/.local/share/code-server/extensions/ms-python.python-2023.4.1/pythonFiles/printEnvVariables.py
Running Env creation script:  [
  '/bin/python3',
  '/home/ubuntu/.local/share/code-server/extensions/ms-python.python-2023.4.1/pythonFiles/create_venv.py',
  '--git-ignore',
  '--toml',
  '/mnt/code/pyproject.toml'
]
Running: /bin/python3 -m venv .venv

The virtual environment was not created successfully because ensurepip is not
available.  On Debian/Ubuntu systems, you need to install the python3-venv
package using the following command.

    apt install python3.8-venv

You may need to use sudo with that command.  After installing the python3-venv
package, recreate your virtual environment.

Failing command: ['/mnt/code/.venv/bin/python3', '-Im', 'ensurepip', '--upgrade', '--default-pip']


Traceback (most recent call last):
  File "/home/ubuntu/.local/share/code-server/extensions/ms-python.python-2023.4.1/pythonFiles/create_venv.py", line 75, in run_process

    subprocess.run(args, cwd=os.getcwd(), check=True)
  File "/usr/lib/python3.8/subprocess.py", line 516, in run

    raise CalledProcessError(retcode, process.args,
subprocess.CalledProcessError: Command '['/bin/python3', '-m', 'venv', '.venv']' returned non-zero exit status 1.


During handling of the above exception, another exception occurred:

Traceback (most recent call last):
  File "/home/ubuntu/.local/share/code-server/extensions/ms-python.python-2023.4.1/pythonFiles/create_venv.py", line 167, in <module>
    main(sys.argv[1:])
  File "/home/ubuntu/.local/share/code-server/extensions/ms-python.python-2023.4.1/pythonFiles/create_venv.py", line 145, in main
    run_process(
  File "/home/ubuntu/.local/share/code-server/extensions/ms-python.python-2023.4.1/pythonFiles/create_venv.py", line 77, in run_process
    raise VenvError(error_message)
__main__.VenvError: 
CREATE_VENV.VENV_FAILED_CREATION

[ERROR 2025-5-9 17:4:16.95]: Error while running venv creation script:  CREATE_VENV.VENV_FAILED_CREATION
[ERROR 2025-5-9 17:4:16.95]: CREATE_VENV.VENV_FAILED_CREATION
